Workbook

Sheet Pozycje
A1: ID | B1: Sekcja | C1: Podsekcja | D1: Lp./Ref | E1: Pozycja | F1: Ilość z dokumentu | G1: Ilość do wyceny | H1: Opis / zakres | I1: Cena jedn. netto [PLN] | J1: Wartość netto [PLN] | K1: Uwagi wykonawcy
A2: AUT-001 | B2: Automatyka KNX | C2: Urządzenia systemowe | E2: Obwody oświetlenia On/Off | F2: 41 | G2: 41 | H2: Sterowanie oświetleniem klasycznym, w domu oraz terenie zewnętrznym. | J2: =IF(OR(G2="",I2=""),"",G2*I2)
A3: AUT-002 | B3: Automatyka KNX | C3: Urządzenia systemowe | E3: Obwody oświetlenia ściemnianego fazowo | F3: 4 | G3: 4 | H3: Sterowanie oświetleniem ściemnianym klasycznie. | J3: =IF(OR(G3="",I3=""),"",G3*I3)
A4: AUT-003 | B4: Automatyka KNX | C4: Urządzenia systemowe | E4: Obwody oświetlenia ściemnianego LED RGBW | F4: 0 | G4: 0 | H4: Sterowanie ściemnianymi paskami LED RGBW (ustawianie koloru). | J4: =IF(OR(G4="",I4=""),"",G4*I4)
A5: AUT-004 | B5: Automatyka KNX | C5: Urządzenia systemowe | E5: Obwody oświetlenia ściemnianego LED MONO | F5: 12 | G5: 12 | H5: Sterowanie ściemnianymi paskami LED jednobarwnymi. | J5: =IF(OR(G5="",I5=""),"",G5*I5)
A6: AUT-005 | B6: Automatyka KNX | C6: Urządzenia systemowe | E6: Inne elementy sterowane | F6: 3 | G6: 3 | H6: Inne obwody sterowane impulsowo lub napięciowo: bramy, furtki, zawory, itp. | J6: =IF(OR(G6="",I6=""),"",G6*I6)
A7: AUT-006 | B7: Automatyka KNX | C7: Urządzenia systemowe | E7: Przesłony okienne | F7: 12 | G7: 12 | H7: Sterowanie mechanizmami żaluzji, rolet, zasłon, firan, itp. | J7: =IF(OR(G7="",I7=""),"",G7*I7)
A8: AUT-007 | B8: Automatyka KNX | C8: Urządzenia systemowe | E8: Strefy ogrzewania / chłodzenia | F8: 17 | G8: 17 | H8: Sterowanie temperaturą w pomieszczeniach. | J8: =IF(OR(G8="",I8=""),"",G8*I8)
A9: AUT-008 | B9: Automatyka KNX | C9: Urządzenia systemowe | E9: Multisensor (T, H, M) | F9: 3 | G9: 3 | H9: Sufitowe czujniki temperatury, wilgotności, ruchu. | J9: =IF(OR(G9="",I9=""),"",G9*I9)
A10: AUT-009 | B10: Automatyka KNX | C10: Urządzenia systemowe | E10: Czujnik ruchu - wewnętrzny | F10: 7 | G10: 7 | H10: Sufitowy, wewnętrzny czujnik ruchu. | J10: =IF(OR(G10="",I10=""),"",G10*I10)
A11: AUT-010 | B11: Automatyka KNX | C11: Urządzenia systemowe | E11: Czujnik jakości powietrza (T, H, CO2, VOC) | F11: 1 | G11: 1 | H11: Czujnik jakości powietrza: temp., wilg., CO2, lotne związki organiczne. | J11: =IF(OR(G11="",I11=""),"",G11*I11)
A12: AUT-011 | B12: Automatyka KNX | C12: Urządzenia systemowe | E12: Stacja METEO / Zewnętrzny czujnik temperatury | F12: 0 | G12: 0 | H12: Czujnik temperatury na elewację - T | J12: =IF(OR(G12="",I12=""),"",G12*I12)
A13: AUT-012 | B13: Automatyka KNX | C13: Urządzenia systemowe | E13: Bramka KNX-IP | F13: 1 | G13: 1 | H13: Interface do komunikacji sieciowej. | J13: =IF(OR(G13="",I13=""),"",G13*I13)
... A21: AUT-020 | B21: Automatyka KNX | C21: Urządzenia systemowe | E21: Ramka do iPada (11”) + ładowarka podtynkowa | F21: 0 | G21: 0 | H21: Ramka do iPada 11 generacji (11”) w kolorze czarnym + ładowarka USB-C | J21: =IF(OR(G21="",I21=""),"",G21*I21)
A22: AUT-021 | B22: Automatyka KNX | C22: Urządzenia systemowe | E22: iPad 11” (Gen 11) | F22: 0 | G22: 0 | J22: =IF(OR(G22="",I22=""),"",G22*I22)
A23: AUT-022 | B23: Automatyka KNX | C23: Urządzenia systemowe | E23: Integracja z systemem wentylacji mechanicznej | F23: TAK | G23: 1 | H23: Wymagana centrala wentylacyjna z interfejsem KNX lub MODBUS. | J23: =IF(OR(G23="",I23=""),"",G23*I23)
A24: AUT-023 | B24: Automatyka KNX | C24: Urządzenia systemowe | E24: Integracja z systemem klimatyzacji | F24: TAK | G24: 1 | H24: Wymagana jednostka z interfejsem KNX lub MODBUS. | J24: =IF(OR(G24="",I24=""),"",G24*I24)
A25: AUT-024 | B25: Automatyka KNX | C25: Urządzenia systemowe | E25: Integracja z systemem alarmowym | F25: TAK | G25: 1 | H25: Wymagany Satel Integra z kartą INT-KNX. | J25: =IF(OR(G25="",I25=""),"",G25*I25)
A26: AUT-025 | B26: Automatyka KNX | C26: Urządzenia systemowe | E26: Integracja z systemem PV hybrydowym | F26: TAK | G26: 1 | H26: Wymagany inwerter z interfejsem MODBUS oraz dokumentacja. | J26: =IF(OR(G26="",I26=""),"",G26*I26)
A27: AUT-026 | B27: Automatyka KNX | C27: Urządzenia systemowe | E27: Integracja z pompą ciepła | F27: NIE | G27: 0 | H27: Wymagana jednostka z interfejsem KNX lub MODBUS oraz dokumentacja. | J27: =IF(OR(G27="",I27=""),"",G27*I27)
A28: AUT-027 | B28: Automatyka KNX | C28: Urządzenia systemowe | E28: Asystent oświetlenia | F28: TAK | G28: 1 | H28: Podstawowa automatyzacja oświetlenia. | J28: =IF(OR(G28="",I28=""),"",G28*I28)
A29: AUT-028 | B29: Automatyka KNX | C29: Urządzenia systemowe | E29: Asystent przesłon okiennych | F29: TAK | G29: 1 | H29: Podstawowa automatyzacja sterowania przesłonami / roletami. | J29: =IF(OR(G29="",I29=""),"",G29*I29)
A30: AUT-029 | B30: Automatyka KNX | C30: Urządzenia systemowe | E30: Asystent wentylacji | F30: TAK | G30: 1 | H30: Podstawowa automatyzacja systemu wentylacji. | J30: =IF(OR(G30="",I30=""),"",G30*I30)
A31: AUT-030 | B31: Automatyka KNX | C31: Urządzenia systemowe | E31: Asystent energii | F31: NIE | G31: 0 | H31: Podstawowy monitoring zużycia energii. | J31: =IF(OR(G31="",I31=""),"",G31*I31)
A32: AUT-031 | B32: Automatyka KNX | C32: Urządzenia systemowe | E32: Asystent głosowy | F32: NIE | G32: 0 | H32: Google Home – wybrane komendy. | J32: =IF(OR(G32="",I32=""),"",G32*I32)
A33: PRZ-001 | B33: Przyciski systemowe | C33: Panele | E33: Panel systemowy KNX – 1 przycisk | F33: 0 | G33: 0 | H33: JUNG LS 990 F40/F50 aluminium dark | J33: =IF(OR(G33="",I33=""),"",G33*I33)
A34: PRZ-002 | B34: Przyciski systemowe | C34: Panele | E34: Panel systemowy KNX – 2 przyciski | F34: 6 | G34: 6 | H34: JUNG LS 990 F40/F50 aluminium dark | J34: =IF(OR(G34="",I34=""),"",G34*I34)
A35: PRZ-003 | B35: Przyciski systemowe | C35: Panele | E35: Panel systemowy KNX – 4 przyciski | F35: 40 | G35: 40 | H35: JUNG LS 990 F40/F50 aluminium dark | J35: =IF(OR(G35="",I35=""),"",G35*I35)
A36: PRZ-004 | B36: Przyciski systemowe | C36: Panele | E36: Panel systemowy KNX – LCD | F36: 0 | G36: 0 | H36: JUNG LS Touch aluminium dark | J36: =IF(OR(G36="",I36=""),"",G36*I36)
A37: PRA-001 | B37: Prace (robocizna) | C37: Usługi | E37: Montaż i uruchomienie | F37: 1 | G37: 1 | H37: Montaż elementów w przygotowanych miejscach (puszki elektryczne, rozdzielnia). | J37: =IF(OR(G37="",I37=""),"",G37*I37)
A38: PRA-002 | B38: Prace (robocizna) | C38: Usługi | E38: Programowanie + wizualizacja | F38: 1 | G38: 1 | H38: Zaprogramowanie powiązań elementów sterujących i wykonawczych, logika, automatyzacja, indywidualna aplikacja do zarządzania funkcjami automatyki (sterowanie, statusy, itd.) na iOS, Android, PC. | J38: =IF(OR(G38="",I38=""),"",G38*I38)
A39: SIE-001 | B39: Sieć LAN/WiFi | C39: Urządzenia i akcesoria | D39: 1 | E39: Ubiquiti Dream Machine Pro | F39: 1 | G39: 1 | H39: Zaawansowany router z firewallem oraz kontrolerem sieci WiFi. Cena źródłowa obejmowała montaż standardowy, uruchomienie oraz podstawową konfigurację. | J39: =IF(OR(G39="",I39=""),"",G39*I39)
A40: SIE-002 | B40: Sieć LAN/WiFi | C40: Urządzenia i akcesoria | D40: 2 | E40: Ubiquiti USW-PRO-24-POE | F40: 1 | G40: 1 | H40: Switch zarządzalny L2/L3 Gigabit Ethernet (10/100/1000) - 16x GbE PoE+ (802.3at/af), 8x GbE PoE ++, 2x SFP+. | J40: =IF(OR(G40="",I40=""),"",G40*I40)
A41: SIE-003 | B41: Sieć LAN/WiFi | C41: Urządzenia i akcesoria | D41: 3 | E41: Ubiquiti USW-24 | F41: 1 | G41: 1 | H41: Switch zarządzalny L2/L3 Gigabit Ethernet (10/100/1000) - 24x GbE, 2x SFP+. | J41: =IF(OR(G41="",I41=""),"",G41*I41)
A42: SIE-004 | B42: Sieć LAN/WiFi | C42: Urządzenia i akcesoria | D42: 4 | E42: Ubiquiti UACC-DAC-SFP10-0.5M | F42: 2 | G42: 2 | H42: SFP+ - Direct Attach Copper Cable, 10Gbps, 0.5M. Kabel do łączenia aktywnych urządzeń sieciowych. | J42: =IF(OR(G42="",I42=""),"",G42*I42)
A43: SIE-005 | B43: Sieć LAN/WiFi | C43: Urządzenia i akcesoria | D43: 5 | E43: Ubiquiti U6-LR | F43: 6 | G43: 6 | H43: Wewnętrzny punkt dostępowy ze standardem WiFi 6 - UniFi 6 Long-Range 3000 Mbit/s, biały. | J43: =IF(OR(G43="",I43=""),"",G43*I43)
A44: SIE-006 | B44: Sieć LAN/WiFi | C44: Urządzenia i akcesoria | D44: 6 | E44: Ubiquiti U6-Mesh-Pro | F44: 2 | G44: 2 | H44: Zewnętrzny punkt dostępowy WiFi 6 z 4 strumieniami przestrzennymi, zintegrowaną super anteną i portem o przepustowości gigabit. | J44: =IF(OR(G44="",I44=""),"",G44*I44)
A45: SIE-007 | B45: Sieć LAN/WiFi | C45: Urządzenia i akcesoria | D45: 7 | E45: Patchpanel modularny 24p | F45: 2 | G45: 2 | H45: Panel krosowy modularny 19" 24x keystone, ekranowany, 1U, czarny, prowadnica kabli, pola opisowe. | J45: =IF(OR(G45="",I45=""),"",G45*I45)
A46: SIE-008 | B46: Sieć LAN/WiFi | C46: Urządzenia i akcesoria | D46: 8 | E46: Keystone RJ45 (8P8C) kat.6A | F46: 48 | G46: 48 | H46: Moduł (gniazdo) keystone RJ45 (8P8C) kat.6A, STP, ekranowany, beznarzędziowy, stalowy. | J46: =IF(OR(G46="",I46=""),"",G46*I46)
A47: SIE-009 | B47: Sieć LAN/WiFi | C47: Urządzenia i akcesoria | D47: 9 | E47: Patchcord LAN kat. 6, kolor, 0,5m | F47: 48 | G47: 48 | H47: Kabel sieciowy, miedziany. Patchcord LAN o długości pół metra. | J47: =IF(OR(G47="",I47=""),"",G47*I47)
...

Sheet Podsumowanie
A1: Podsumowanie oferty
A3: Stawka VAT | B3: 0.08
A5: Sekcja | B5: Wartość netto [PLN]
A6: Automatyka KNX | B6: =SUMIF(Pozycje!$B$2:$B$135,A6,Pozycje!$J$2:$J$135) -> 0
A7: Przyciski systemowe | B7: =SUMIF(Pozycje!$B$2:$B$135,A7,Pozycje!$J$2:$J$135) -> 0
A8: Prace (robocizna) | B8: =SUMIF(Pozycje!$B$2:$B$135,A8,Pozycje!$J$2:$J$135) -> 0
A9: Sieć LAN/WiFi | B9: =SUMIF(Pozycje!$B$2:$B$135,A9,Pozycje!$J$2:$J$135) -> 0
A10: System alarmowy | B10: =SUMIF(Pozycje!$B$2:$B$135,A10,Pozycje!$J$2:$J$135) -> 0
A11: Monitoring wideo | B11: =SUMIF(Pozycje!$B$2:$B$135,A11,Pozycje!$J$2:$J$135) -> 0
A12: Wideo domofon IP | B12: =SUMIF(Pozycje!$B$2:$B$135,A12,Pozycje!$J$2:$J$135) -> 0
A13: Rozdzielnica elektryczna | B13: =SUMIF(Pozycje!$B$2:$B$135,A13,Pozycje!$J$2:$J$135) -> 0
A14: Opracowanie / plany | B14: =SUMIF(Pozycje!$B$2:$B$135,A14,Pozycje!$J$2:$J$135) -> 0
A16: Razem netto | B16: =SUM(B6:B14) -> 0
A17: VAT | B17: =B16*$B$3 -> 0
A18: Wskazówka: | B18: =B16+B17 -> 0
